Workbook

Sheet PLANILHA MESTRE
A1: PLANILHA INVENTÁRIO 2026 FORNECEDOR BARELLA
A3: 46220 | E3: ESTRUTURA DE COMPONENTES - INJEÇÃO EXTERNA
A4: CÓDIGO | B4: PRODUTO | D4: PP NAT. FLUIDEZ 14 A 26 (HP 550R) 0049-01 | E4: 0050-03 POLIAMIDA 13% | F4: MASTER PRETO 0053-19 | G4: MASTER VERMELHO (RED LINE) 0053-80 | H4: MASTER BRANCO 0053-01 | I4: MASTER AMARELO 0053-90 | J4: ETIQ. INOX L-1000 1316-42 | K4: ETIQ. INOX L-99 1316-66 | L4: PP NAT. FLUIDEZ 2,5 A 4,5 (HP 550K 0049-04 | M4: TOMADA AZUL VT-41-TM 0321-94 | N4: 1316-27 ETIQUETA INOX BOTÃO L-850 | O4: 0052-01 POLIACETAL | P4: 0308-16 CONTATO I | Q4: 0152-00 ETIQUETA DO BOTÃO L-61 | R4: MASTER BRANCO REMARFIN 0053-54 | S4: MASTER PRATA 0053-91 | T4: MASTER MARSALA | U4: PEBD ANTICHAMA | V4: ETIQUETA INOX COOKTOP | W4: MOLA COOKTOP Antiga | X4: PORCA M8 | Y4: MASTER PRATA(0053-90) | Z4: ABS NATURAL | AA4: MASTER PRETO ABS | AB4: SAM | AC4: ETIQUETA DO LD AF 0197-35 | AD4: MASTER RED ABS | AE4: 0049-30 PP NAT. FLUIDEZ 26 (CP 202XP) | AF4: 0153-03 SAN VERMELHO (MASTERIZADO) | AG4: MOLA DO MANIPULO [ VERSÃO B ] | AH4: Master Verde Palmeiras | AI4: Master Vermelho São Paulo | AJ4: Etiqueta do L99 polido | AK4: PBT PRETO | AL4: MASTER AZUL | AM4: MASTER PRETO CP 202XP | AN4: master preto AFON 0054-66 | AO4: etiqueta AF texturizada 0210-00 | AP4: ETIQUETA DA AF 0120-03 | AQ4: SACO PLÁSTICO 18X20 0118-43
A5: 0218-15 | B5: ETIQUETA LOGO PRETA [V-45] | D5: 0.01691 | F5: 0.000258
A6: 0245-16 | B6: ETIQUETA VT-40 PRATA | D6: 0.00886 | Y6: 0.000274
A7: 0245-18 | B7: ETIQUETA LOGO BRANCA [V-40] | D7: 0.01691 | R7: 0.000345
A8: 0245-15 | B8: ETIQUETA VT-30 PRATA | D8: 0.005626 | Y8: 0.000174
A9: 0067-19 | B9: BOTÃO VT-30/40 PRETO | D9: 0.005472 | F9: 8.3e-05
A10: 0066-14 | B10: BOTÃO DA HELICE PRATA + PORCA | C10: 3277 | D10: 0.006276 | S10: 0.000194 | X10: 0.001
A11: Injetado | B11: BOTÃO DA HELICE PRATA S/ PORCA | D11: 0.006276 | S11: 0.000194
A12: 0066-08 | B12: BOTÃO DA HELICE PRETA C/ PORCA | D12: 0.006372 | F12: 9.7e-05 | X12: 0.001
A13: 0066-89 | B13: BOTÃO DA HELICE AZUL C/ PORCA | C13: 6283 | D13: 0.006341 | X13: 1 | AL13: 0.00129
A14: Injetado | B14: BOTÃO DA HELICE PRETA S/ PORCA | D14: 0.006372 | F14: 9.7e-05
A15: 0066-12 | B15: BOTÃO DA HELICE RED LINE + PORCA | D15: 0.006341 | G15: 0.000129 | X15: 0.001
A16: Injetado | B16: BOTÃO DA HELICE RED LINE S/ PORCA | D16: 0.006341 | G16: 0.000129
A17: 1316-74 | B17: BOTÃO L/D BATEDEIRA PLANETARIA VERMELHO [BP] | D17: 0.01078 | G17: 0.00022
A18: 1316-74 | B18: BOTÃO L/D BATEDEIRA PLANETARIA BRANCO [BP] | D18: 0.01078 | H18: 0.00022
A19: Injetado | B19: BOTAO L/D BATEDEIRA PLANETARIA PRETO BP | D19: 0.010835 | F19: 0.000165
A20: Injetado | B20: BOTÃO L/D BATEDEIRA PLANETARIA MARSALA [BP] | D20: 0.01078 | T20: 0.00022
A21: 1316-48 | B21: BOTÃO L/D LIQUID L-1000 RED+ETIQUETA INOX | D21: 0.008753 | G21: 0.000178 | J21: 0.001
A22: Injetado | B22: BOTÃO L/D LIQUID L-1000 RED | D22: 0.008753 | G22: 0.000178
A23: 1316-41 | B23: BOTÃO L/D LIQUID L-1000 PR+ETIQUETA INOX | C23: 3100 | D23: 0.0088 | F23: 0.000132 | J23: 0.001
A24: Injetado | B24: BOTÃO L/D LIQUID L-1000 PR | D24: 0.0088 | F24: 0.000132
A25: 1316-85 | B25: BOTÃO L/D LIQUID L-1000 MARSALA + ETIQ INOX | D25: 0.0088 | J25: 0.001 | T25: 0.000178
A26: Injetado | B26: BOTÃO L/D LIQUID L-1000 MARSALA | D26: 0.0088 | T26: 0.000178
A27: 0310-38 | B27: BOTÃO FLANGEADO PRETO + ETIQUETA INOX L-850 | D27: 0.011 | F27: 0.000165 | N27: 0.001
A28: Injetado | B28: BOTÃO FLANGEADO PRETO | D28: 0.011 | F28: 0.000165
A29: 0310-47 | B29: BOTÃO FLANGEADO [L-850] VERMELHO + ETIQUETA INOX L-850 | D29: 0.010941 | G29: 0.000223 | N29: 0.001
A30: Injetado | B30: BOTÃO FLANGEADO [L-850] VERMELHO | D30: 0.010941 | G30: 0.000223
A31: 1317-24 | B31: BOTÃO L/D BATEDEIRA PLANETARIA VERMELHO Polishop | D31: 0.010835
A32: 1316-68 | B32: BOTÃO L/D L-1200 PRETO + ETIQUETA INOX | D32: 0.0099 | F32: 0.000148 | J32: 0.001
A33: Injetado | B33: BOTÃO L/D L-1200 PRETO | D33: 0.0099 | F33: 0.000148
A34: 1316-67 | B34: BOTÃO L/D L-1200 VERMELHO + ETIQUETA INOX | D34: 0.009847 | G34: 0.0002 | J34: 0.001
A35: Injetado | B35: BOTÃO L/D L-1200 VERMELHO | D35: 0.009847 | G35: 0.0002
B36: BOTÃO L/D L-1200 Azul polisho acabado | D36: 0.009847
B37: BOTÃO L/D L-1200 Marsala acabado | D37: 0.009847
B38: BOTÃO L/D L-1200 Marsala injetado | D38: 0.009847
B39: BOTÃO L/D L-1200 VERMELHO polishop acabado | D39: 0.009847
A40: 1316-06 | B40: BOTÃO LIQUID. L-61 + ETIQ. INOX | D40: 0.006919 | F40: 0.000141 | Q40: 0.001
A41: Injetado | B41: BOTÃO LIQUID. L-61 | D41: 0.006919 | F41: 0.000141
...

Sheet EXPLOSÃO
B1: PLANILHA MESTRE (EXPLOSÃO)
B3: PP VS + MASTER PRETO BATCH 0053-19 | G3: PP + MASTER VERMELHO 0053-80 | L3: PP VS+ MASTER BRANCO 0053-01 | Q3: PP VS+ MASTER MARSALA
B4: ESTADO | C4: QUANTIDADE | D4: PPVS | E4: MASTER PRETO | G4: ESTADO | H4: QUANTIDADE | I4: PPVS | J4: MASTER RED | L4: ESTADO | M4: QUANTIDADE | N4: PP VS | O4: MASTER BRANCO | Q4: ESTADO | R4: QUANTIDADE | S4: PP VS | T4: MASTER MARSALA
B5: BORRA | C5: 531.158 | D5: =C5-E5 -> 523.19063 | E5: =C5*1.5% -> 7.96737 | G5: BORRA | H5: 30 | I5: =H5-J5 -> 29.4 | J5: =H5*2% -> 0.6 | L5: BORRA | M5: 140.46 | N5: =M5-O5 -> 137.6508 | O5: =M5*2% -> 2.8092 | Q5: BORRA | S5: =R5-T5 -> 0 | T5: =R5*2% -> 0
B6: MISTURA | D6: =C6-E6 -> 0 | E6: =C6*1.5% -> 0 | G6: MISTURA | I6: =H6-J6 -> 0 | J6: =H6*2% -> 0 | L6: MISTURA | N6: =M6-O6 -> 0 | O6: =M6*2% -> 0 | Q6: MISTURA | S6: =R6-T6 -> 0 | T6: =R6*2% -> 0
B7: GALHO | D7: =C7-E7 -> 0 | E7: =C7*1.5% -> 0 | G7: GALHO | I7: =H7-J7 -> 0 | J7: =H7*2% -> 0 | L7: GALHO | N7: =M7-O7 -> 0 | O7: =M7*2% -> 0 | Q7: GALHO | S7: =R7-T7 -> 0 | T7: =R7*2% -> 0
B8: VARREDURA | D8: =C8-E8 -> 0 | E8: =C8*1.5% -> 0 | G8: VARREDURA | I8: =H8-J8 -> 0 | J8: =H8*2% -> 0 | L8: VARREDURA | N8: =M8-O8 -> 0 | O8: =M8*2% -> 0 | Q8: VARREDURA | S8: =R8-T8 -> 0 | T8: =R8*2% -> 0
B9: MOIDO | C9: 8836.81 | D9: =C9-E9 -> 8704.2578 | E9: =C9*1.5% -> 132.55215 | G9: MOÍDO | H9: 374.8 | I9: =H9-J9 -> 367.304 | J9: =H9*2% -> 7.496 | L9: MOÍDO | M9: 429.372 | N9: =M9-O9 -> 420.78456 | O9: =M9*2% -> 8.58744 | Q9: MOÍDO | S9: =R9-T9 -> 0 | T9: =R9*2% -> 0
B10: SUCATA | D10: =C10-E10 -> 0 | E10: =C10*1.5% -> 0 | G10: SUCATA | I10: =H10-J10 -> 0 | J10: =H10*2% -> 0 | L10: SUCATA | N10: =M10-O10 -> 0 | O10: =M10*2% -> 0 | Q10: SUCATA | S10: =R10-T10 -> 0 | T10: =R10*2% -> 0
B11: MÁQUINA | D11: =C11-E11 -> 0 | E11: =C11*1.5% -> 0 | G11: MÁQUINA | I11: =H11-J11 -> 0 | J11: =H11*2% -> 0 | L11: MÁQUINA | N11: =M11-O11 -> 0 | O11: =M11*2% -> 0 | Q11: MÁQUINA | S11: =R11-T11 -> 0 | T11: =R11*2% -> 0
B12: TOTAL REFUGO | C12: =SUM(C5:C11) -> 9367.968 | D12: =SUM(D5:D11) -> 9227.4485 | E12: =SUM(E5:E11) -> 140.51952 | G12: TOTAL REFUGO | H12: =SUM(H5:H11) -> 404.8 | I12: =SUM(I5:I11) -> 396.704 | J12: =SUM(J5:J11) -> 8.096 | L12: TOTAL REFUGO | M12: =SUM(M5:M11) -> 569.832 | N12: =SUM(N5:N11) -> 558.43536 | O12: =SUM(O5:O11) -> 11.39664 | Q12: TOTAL REFUGO | R12: =SUM(R5:R11) -> 0 | S12: =SUM(S5:S11) -> 0 | T12: =SUM(T5:T11) -> 0
B14: PP MASTER CINZA | G14: PP MASTER PRATA 0053-90 | L14: PP KM + BRANCO 0053-01 | Q14: PP MASTER AMARELO
B15: ESTADO | C15: QUANTIDADE | D15: PP VS | E15: MASTER PRETO | G15: ESTADO | H15: QUANTIDADE | I15: PP VS | J15: MASTER PRATA | L15: ESTADO | M15: QUANTIDADE | N15: PP KM | O15: MASTER BRANCO PP | Q15: ESTADO | R15: QUANTIDADE | S15: POLIACETAL | T15: MASTER AMARELO
B16: BORRA | D16: =C16-E16 -> 0 | E16: =C16*2% -> 0 | G16: BORRA | I16: =H16-J16 -> 0 | J16: =H16*3% -> 0 | L16: BORRA | N16: =M16-O16 -> 0 | O16: =M16*2% -> 0 | Q16: BORRA | S16: =R16-T16 -> 0 | T16: =R16*2% -> 0
B17: MISTURA | D17: =C17-E17 -> 0 | E17: =C17*2% -> 0 | G17: MISTURA | I17: =H17-J17 -> 0 | J17: =H17*3% -> 0 | L17: MISTURA | N17: =M17-O17 -> 0 | O17: =M17*2% -> 0 | Q17: MISTURA | S17: =R17-T17 -> 0 | T17: =R17*2% -> 0
B18: GALHO | D18: =C18-E18 -> 0 | E18: =C18*2% -> 0 | G18: GALHO | I18: =H18-J18 -> 0 | J18: =H18*3% -> 0 | L18: GALHO | N18: =M18-O18 -> 0 | O18: =M18*2% -> 0 | Q18: GALHO | S18: =R18-T18 -> 0 | T18: =R18*2% -> 0
B19: VARREDURA | D19: =C19-E19 -> 0 | E19: =C19*2% -> 0 | G19: VARREDURA | I19: =H19-J19 -> 0 | J19: =H19*3% -> 0 | L19: VARREDURA | N19: =M19-O19 -> 0 | O19: =M19*2% -> 0 | Q19: VARREDURA | S19: =R19-T19 -> 0 | T19: =R19*2% -> 0
B20: MOÍDO | D20: =C20-E20 -> 0 | E20: =C20*2% -> 0 | G20: MOÍDO | H20: 325.5 | I20: =H20-J20 -> 315.735 | J20: =H20*3% -> 9.765 | L20: MOÍDO | N20: =M20-O20 -> 0 | O20: =M20*2% -> 0 | Q20: MOÍDO | S20: =R20-T20 -> 0 | T20: =R20*2% -> 0
B21: SUCATA | D21: =C21-E21 -> 0 | E21: =C21*2% -> 0 | G21: SUCATA | I21: =H21-J21 -> 0 | J21: =H21*3% -> 0 | L21: SUCATA | N21: =M21-O21 -> 0 | O21: =M21*2% -> 0 | Q21: SUCATA | S21: =R21-T21 -> 0 | T21: =R21*2% -> 0
B22: MÁQUINA | D22: =C22-E22 -> 0 | E22: =C22*2% -> 0 | G22: MÁQUINA | I22: =H22-J22 -> 0 | J22: =H22*3% -> 0 | L22: MÁQUINA | N22: =M22-O22 -> 0 | O22: =M22*2% -> 0 | Q22: MÁQUINA | S22: =R22-T22 -> 0 | T22: =R22*2% -> 0
B23: TOTAL REFUGO | C23: =SUM(C16:C22) -> 0 | D23: =SUM(D16:D22) -> 0 | E23: =SUM(E16:E22) -> 0 | G23: TOTAL REFUGO | H23: =SUM(H16:H22) -> 325.5 | I23: =SUM(I16:I22) -> 315.735 | J23: =SUM(J16:J22) -> 9.765 | L23: TOTAL REFUGO | M23: =SUM(M16:M22) -> 0 | N23: =SUM(N16:N22) -> 0 | O23: =SUM(O16:O22) -> 0 | Q23: TOTAL REFUGO | S23: =SUM(S16:S22) -> 0 | T23: =SUM(T16:T22) -> 0
B25: PP KM + MASTER Chumbo 0054-75 | G25: PP VS + MASTER PRATA 0053-91 BOTÃO | L25: PP VS + MASTER CINZA 0053-16 | Q25: PP VS+ MASTER BR REMARFIM 0053-54
B26: ESTADO | C26: QUANTIDADE | D26: PP VS | E26: MASTER BR | G26: ESTADO | H26: QUANTIDADE | I26: PP VS | J26: MASTER PRAT | L26: ESTADO | M26: QUANTIDADE | N26: PP VS | O26: MASTER CINZA | Q26: ESTADO | R26: QUANTIDADE | S26: PP VS | T26: MASTER BR
B27: BORRA | D27: =C27-E27 -> 0 | E27: =C27*2% -> 0 | G27: BORRA | I27: =H27-J27 -> 0 | J27: =H27*3% -> 0 | L27: BORRA | N27: =M27-O27 -> 0 | O27: =M27*1% -> 0 | Q27: BORRA | S27: =R27-T27 -> 0 | T27: =R27*2% -> 0
B28: MISTURA | D28: =C28*0.98 -> 0 | E28: =C28*0.03 -> 0 | G28: MISTURA | I28: =H28-J28 -> 0 | J28: =H28*3% -> 0 | L28: MISTURA | N28: =M28-O28 -> 0 | O28: =M28*1% -> 0 | Q28: MISTURA | S28: =R28-T28 -> 0 | T28: =R28*2% -> 0
B29: GALHO | G29: GALHO | I29: =H29-J29 -> 0 | J29: =H29*3% -> 0 | L29: GALHO | N29: =M29-O29 -> 0 | O29: =M29*1% -> 0 | Q29: GALHO | S29: =R29-T29 -> 0 | T29: =R29*2% -> 0
B30: VARREDURA | D30: =R30-E30 -> 0 | E30: =R30*2% -> 0 | G30: VARREDURA | I30: =H30-J30 -> 0 | J30: =H30*3% -> 0 | L30: VARREDURA | N30: =M30-O30 -> 0 | O30: =M30*1% -> 0 | Q30: VARREDURA | S30: =R30-T30 -> 0 | T30: =R30*2% -> 0
B31: MOÍDO | D31: =C31*0.98 -> 0 | E31: =C31*0.03 -> 0 | G31: MOÍDO | H31: 172.9 | I31: =H31-J31 -> 167.713 | J31: =H31*3% -> 5.187 | L31: MOÍDO | N31: =M31-O31 -> 0 | O31: =M31*1% -> 0 | Q31: MOÍDO | R31: 1532 | S31: =R31-T31 -> 1501.36 | T31: =R31*2% -> 30.64
B32: SUCATA | D32: =R32-E32 -> 0 | E32: =R32*2% -> 0 | G32: SUCATA | I32: =H32-J32 -> 0 | J32: =H32*3% -> 0 | L32: SUCATA | N32: =M32-O32 -> 0 | O32: =M32*1% -> 0 | Q32: SUCATA | S32: =R32-T32 -> 0 | T32: =R32*2% -> 0
B33: MÁQUINA | D33: =C33-E33 -> 0 | E33: =C33*2% -> 0 | G33: MÁQUINA | I33: =H33-J33 -> 0 | J33: =H33*3% -> 0 | L33: MÁQUINA | N33: =M33-O33 -> 0 | O33: =M33*1% -> 0 | Q33: MÁQUINA | S33: =R33-T33 -> 0 | T33: =R33*2% -> 0
B34: TOTAL REFUGO | C34: =SUM(C27:C33) -> 0 | D34: =SUM(D27:D33) -> 0 | E34: =SUM(E27:E33) -> 0 | G34: TOTAL REFUGO | H34: =SUM(H27:H33) -> 172.9 | I34: =SUM(I27:I33) -> 167.713 | J34: =SUM(J27:J33) -> 5.187 | L34: TOTAL REFUGO | M34: =SUM(M27:M33) -> 0 | N34: =SUM(N27:N33) -> 0 | O34: =SUM(O27:O33) -> 0 | Q34: TOTAL REFUGO | R34: =SUM(R27:R33) -> 1532 | S34: =SUM(S27:S33) -> 1501.36 | T34: =SUM(T27:T33) -> 30.64
B36: PP VS + MASTER VERMELHO 0053-56 | G36: Cooktop | L36: PP KM + VERMELHO 0053-80 | Q36: PP KM + PRETO 0053-19
B37: ESTADO | C37: QUANTIDADE | D37: PP VS | E37: MASTER VERM | G37: ESTADO | H37: QUANTIDADE | I37: PP VS | J37: MASTER PRETO | L37: ESTADO | M37: QUANTIDADE | N37: PP KM | O37: MASTER RED | Q37: ESTADO | R37: QUANTIDADE | S37: PP KM | T37: MASTER preto
B38: BORRA | D38: =C38-E38 -> 0 | E38: =C38*2% -> 0 | G38: BORRA | I38: =H38-J38 -> 0 | J38: =H38*3% -> 0 | L38: BORRA | N38: =M38-O38 -> 0 | O38: =M38*2% -> 0 | Q38: BORRA | S38: =R38-T38 -> 0 | T38: =R38*1.5% -> 0
B39: MISTURA | D39: =C39-E39 -> 0 | E39: =C39*2% -> 0 | G39: MISTURA | I39: =H39-J39 -> 0 | J39: =H39*3% -> 0 | L39: MISTURA | N39: =M39-O39 -> 0 | O39: =M39*2% -> 0 | Q39: MISTURA | S39: =R39-T39 -> 0 | T39: =R39*1.5% -> 0
B40: GALHO | D40: =C40-E40 -> 0 | E40: =C40*2% -> 0 | G40: GALHO | I40: =H40-J40 -> 0 | J40: =H40*3% -> 0 | L40: GALHO | N40: =M40-O40 -> 0 | O40: =M40*2% -> 0 | Q40: GALHO | S40: =R40-T40 -> 0 | T40: =R40*1.5% -> 0
B41: VARREDURA | D41: =C41-E41 -> 0 | E41: =C41*2% -> 0 | G41: VARREDURA | I41: =H41-J41 -> 0 | J41: =H41*3% -> 0 | L41: VARREDURA | N41: =M41-O41 -> 0 | O41: =M41*2% -> 0 | Q41: VARREDURA | S41: =R41-T41 -> 0 | T41: =R41*1.5% -> 0
B42: MOÍDO | D42: =C42-E42 -> 0 | E42: =C42*2% -> 0 | G42: MOÍDO | I42: =H42-J42 -> 0 | J42: =H42*3% -> 0 | L42: MOÍDO | M42: 190.06 | N42: =M42-O42 -> 186.2588 | O42: =M42*2% -> 3.8012 | Q42: MOÍDO | R42: 394.1 | S42: =R42-T42 -> 388.1885 | T42: =R42*1.5% -> 5.9115
B43: SUCATA | D43: =C43-E43 -> 0 | E43: =C43*2% -> 0 | G43: SUCATA | I43: =H43-J43 -> 0 | J43: =H43*3% -> 0 | L43: SUCATA | N43: =M43-O43 -> 0 | O43: =M43*2% -> 0 | Q43: SUCATA | S43: =R43-T43 -> 0 | T43: =R43*1.5% -> 0
B44: MÁQUINA | D44: =C44-E44 -> 0 | E44: =C44*2% -> 0 | G44: MÁQUINA | I44: =H44-J44 -> 0 | J44: =H44*3% -> 0 | L44: MÁQUINA | N44: =M44-O44 -> 0 | O44: =M44*2% -> 0 | Q44: MÁQUINA | S44: =R44-T44 -> 0 | T44: =R44*1.5% -> 0
...

Sheet RELATÓRIO DE CONTAGEM
A2: RELATÓRIO DE CONTAGEM DE INVENTÁRIO - BARELLA | H2: ='PLANILHA MESTRE'!A3 -> 46220
C3: =SUBTOTAL(9,C5:C40) -> 868612.41 | D3: =SUBTOTAL(9,D5:D40) -> 478344.1 | E3: =SUBTOTAL(9,E5:E40) -> 387125 | F3: =SUBTOTAL(9,F5:F40) -> -3143.3128
A4: CÓDIGO | B4: DESCRIÇÃO | C4: SALDO DO SISTEMA | D4: SALDO DO INVENTÁRIO | E4: NOTAS EM TRÂNSITO | F4: DIVERGÊNCIA | G4: UNIDADE DE REFERÊNCIA | H4: DIVERGÊNCIA PORCENTAGEM - % | I4: CONDIÇÃO | J4: OBSERVAÇÃO
A5: 0049-01N | B5: =IF(ISERROR(VLOOKUP($A5,'[1]BASE DIVERGÊNCIA'!$A$2:$B$1048576,2,0)),0,VLOOKUP($A5,'[1]BASE DIVERGÊNCIA'!$A$2:$B$1048576,2,0)) -> PP NAT FLUIDEZ 14 À 26 (HP550R) NACIONAL | C5: 37029.507 | D5: ='PLANILHA MESTRE'!O126 -> 21198.609 | E5: =16500 -> 16500 | F5: =D5+E5-C5 -> 669.10211 | G5: =IF(ISERROR(VLOOKUP($A5,'[1]BASE DIVERGÊNCIA'!$A$2:$D$1048576,4,0)),0,VLOOKUP($A5,'[1]BASE DIVERGÊNCIA'!$A$2:$D$1048576,4,0)) -> KG | H5: =IF(OR(C5=0,ISBLANK(C5)),"100%",F5/C5) -> 0.018069431 | I5: =IF(H5<-2%,"VENDA",IF(H5<0%,"AJUSTE DE SAÍDA",IF(H5>0,"AJUSTE DE ENTRADA","SEM DIFERENÇA"))) -> AJUSTE DE ENTRADA | K5: BARELLA PLAST | L5: 1010870 | M5: 03_26
A6: 0049-04 | B6: =IF(ISERROR(VLOOKUP($A6,'[1]BASE DIVERGÊNCIA'!$A$2:$B$1048576,2,0)),0,VLOOKUP($A6,'[1]BASE DIVERGÊNCIA'!$A$2:$B$1048576,2,0)) -> PP NAT FLUIDEZ 2,5 À 4,5 (H503) | C6: 747.953 | D6: ='PLANILHA MESTRE'!O127-400.9416 -> 747.953 | F6: =D6+E6-C6 -> 0 | G6: =IF(ISERROR(VLOOKUP($A6,'[1]BASE DIVERGÊNCIA'!$A$2:$D$1048576,4,0)),0,VLOOKUP($A6,'[1]BASE DIVERGÊNCIA'!$A$2:$D$1048576,4,0)) -> KG | H6: =IF(OR(C6=0,ISBLANK(C6)),"100%",F6/C6) -> 0 | I6: =IF(H6<-2%,"VENDA",IF(H6<0%,"AJUSTE DE SAÍDA",IF(H6>0,"AJUSTE DE ENTRADA","SEM DIFERENÇA"))) -> SEM DIFERENÇA | K6: BARELLA PLAST | L6: 1010870 | M6: 03_26
A7: 0049-27N | B7: =IF(ISERROR(VLOOKUP($A7,'[1]BASE DIVERGÊNCIA'!$A$2:$B$1048576,2,0)),0,VLOOKUP($A7,'[1]BASE DIVERGÊNCIA'!$A$2:$B$1048576,2,0)) -> PEBD ANTI-CHAMA [COOKTOP] | C7: 216.084 | D7: ='PLANILHA MESTRE'!O128 -> 226.25213 | F7: =D7+E7-C7 -> 10.168132 | G7: =IF(ISERROR(VLOOKUP($A7,'[1]BASE DIVERGÊNCIA'!$A$2:$D$1048576,4,0)),0,VLOOKUP($A7,'[1]BASE DIVERGÊNCIA'!$A$2:$D$1048576,4,0)) -> KG | H7: =IF(OR(C7=0,ISBLANK(C7)),"100%",F7/C7) -> 0.047056385 | I7: =IF(H7<-2%,"VENDA",IF(H7<0%,"AJUSTE DE SAÍDA",IF(H7>0,"AJUSTE DE ENTRADA","SEM DIFERENÇA"))) -> AJUSTE DE ENTRADA | K7: BARELLA PLAST | L7: 1010870 | M7: 03_26
A8: 0053-19 | B8: =IF(ISERROR(VLOOKUP($A8,'[1]BASE DIVERGÊNCIA'!$A$2:$B$1048576,2,0)),0,VLOOKUP($A8,'[1]BASE DIVERGÊNCIA'!$A$2:$B$1048576,2,0)) -> MASTER BATCH PRETO | C8: 238.218 | D8: ='PLANILHA MESTRE'!O129-315 -> 47.427399 | E8: 200 | F8: =D8+E8-C8 -> 9.209399 | G8: =IF(ISERROR(VLOOKUP($A8,'[1]BASE DIVERGÊNCIA'!$A$2:$D$1048576,4,0)),0,VLOOKUP($A8,'[1]BASE DIVERGÊNCIA'!$A$2:$D$1048576,4,0)) -> KG | H8: =IF(OR(C8=0,ISBLANK(C8)),"100%",F8/C8) -> 0.038659543 | I8: =IF(H8<-2%,"VENDA",IF(H8<0%,"AJUSTE DE SAÍDA",IF(H8>0,"AJUSTE DE ENTRADA","SEM DIFERENÇA"))) -> AJUSTE DE ENTRADA | K8: BARELLA PLAST | L8: 1010870 | M8: 03_26
A9: 0053-80 | B9: =IF(ISERROR(VLOOKUP($A9,'[1]BASE DIVERGÊNCIA'!$A$2:$B$1048576,2,0)),0,VLOOKUP($A9,'[1]BASE DIVERGÊNCIA'!$A$2:$B$1048576,2,0)) -> MASTER VERMELHO [RED LINE] | C9: 71.353 | D9: ='PLANILHA MESTRE'!O130 -> 42.45672 | E9: 25 | F9: =D9+E9-C9 -> -3.89628 | G9: =IF(ISERROR(VLOOKUP($A9,'[1]BASE DIVERGÊNCIA'!$A$2:$D$1048576,4,0)),0,VLOOKUP($A9,'[1]BASE DIVERGÊNCIA'!$A$2:$D$1048576,4,0)) -> KG | H9: =IF(OR(C9=0,ISBLANK(C9)),"100%",F9/C9) -> -0.054605693 | I9: =IF(H9<-2%,"VENDA",IF(H9<0%,"AJUSTE DE SAÍDA",IF(H9>0,"AJUSTE DE ENTRADA","SEM DIFERENÇA"))) -> VENDA | K9: BARELLA PLAST | L9: 1010870 | M9: 03_26
A10: 1316-42 | B10: =IF(ISERROR(VLOOKUP($A10,'[1]BASE DIVERGÊNCIA'!$A$2:$B$1048576,2,0)),0,VLOOKUP($A10,'[1]BASE DIVERGÊNCIA'!$A$2:$B$1048576,2,0)) -> ETIQ INOX L-1000 | C10: 17904 | D10: ='PLANILHA MESTRE'!O133+7500+800 -> 17103.1 | F10: =D10+E10-C10 -> -800.9 | G10: =IF(ISERROR(VLOOKUP($A10,'[1]BASE DIVERGÊNCIA'!$A$2:$D$1048576,4,0)),0,VLOOKUP($A10,'[1]BASE DIVERGÊNCIA'!$A$2:$D$1048576,4,0)) -> UN | H10: =IF(OR(C10=0,ISBLANK(C10)),"100%",F10/C10) -> -0.044733021 | I10: =IF(H10<-2%,"VENDA",IF(H10<0%,"AJUSTE DE SAÍDA",IF(H10>0,"AJUSTE DE ENTRADA","SEM DIFERENÇA"))) -> VENDA | K10: BARELLA PLAST | L10: 1010870 | M10: 03_26
A11: 1316-66 | B11: =IF(ISERROR(VLOOKUP($A11,'[1]BASE DIVERGÊNCIA'!$A$2:$B$1048576,2,0)),0,VLOOKUP($A11,'[1]BASE DIVERGÊNCIA'!$A$2:$B$1048576,2,0)) -> ETIQUETA INOX ESCOVADO BOTÃO [L-99/VTX] | C11: 470416.75 | D11: ='PLANILHA MESTRE'!O134+22300 -> 204067 | E11: =124800+141600 -> 266400 | F11: =D11+E11-C11 -> 50.25 | G11: =IF(ISERROR(VLOOKUP($A11,'[1]BASE DIVERGÊNCIA'!$A$2:$D$1048576,4,0)),0,VLOOKUP($A11,'[1]BASE DIVERGÊNCIA'!$A$2:$D$1048576,4,0)) -> UN | H11: =IF(OR(C11=0,ISBLANK(C11)),"100%",F11/C11) -> 0.00010682018 | I11: =IF(H11<-2%,"VENDA",IF(H11<0%,"AJUSTE DE SAÍDA",IF(H11>0,"AJUSTE DE ENTRADA","SEM DIFERENÇA"))) -> AJUSTE DE ENTRADA | K11: BARELLA PLAST | L11: 1010870 | M11: 03_26
A12: 0399-60 | B12: =IF(ISERROR(VLOOKUP($A12,'[1]BASE DIVERGÊNCIA'!$A$2:$B$1048576,2,0)),0,VLOOKUP($A12,'[1]BASE DIVERGÊNCIA'!$A$2:$B$1048576,2,0)) -> ETIQUETA DO BOTÃO L/D COOKTOP [CTG] | C12: 23551 | D12: ='PLANILHA MESTRE'!O135-1500 -> 25044 | F12: =D12+E12-C12 -> 1493 | G12: =IF(ISERROR(VLOOKUP($A12,'[1]BASE DIVERGÊNCIA'!$A$2:$D$1048576,4,0)),0,VLOOKUP($A12,'[1]BASE DIVERGÊNCIA'!$A$2:$D$1048576,4,0)) -> UN | H12: =IF(OR(C12=0,ISBLANK(C12)),"100%",F12/C12) -> 0.063394336 | I12: =IF(H12<-2%,"VENDA",IF(H12<0%,"AJUSTE DE SAÍDA",IF(H12>0,"AJUSTE DE ENTRADA","SEM DIFERENÇA"))) -> AJUSTE DE ENTRADA | K12: BARELLA PLAST | L12: 1010870 | M12: 03_26
A13: 0053-01 | B13: =IF(ISERROR(VLOOKUP($A13,'[1]BASE DIVERGÊNCIA'!$A$2:$B$1048576,2,0)),0,VLOOKUP($A13,'[1]BASE DIVERGÊNCIA'!$A$2:$B$1048576,2,0)) -> MASTER BATCH BR-2000 M 1410(PP-BL-30414) | C13: 123.392 | D13: ='PLANILHA MESTRE'!O145-85-5.2 -> 125.7139 | F13: =D13+E13-C13 -> 2.3219 | G13: =IF(ISERROR(VLOOKUP($A13,'[1]BASE DIVERGÊNCIA'!$A$2:$D$1048576,4,0)),0,VLOOKUP($A13,'[1]BASE DIVERGÊNCIA'!$A$2:$D$1048576,4,0)) -> KG | H13: =IF(OR(C13=0,ISBLANK(C13)),"100%",F13/C13) -> 0.018817265 | I13: =IF(H13<-2%,"VENDA",IF(H13<0%,"AJUSTE DE SAÍDA",IF(H13>0,"AJUSTE DE ENTRADA","SEM DIFERENÇA"))) -> AJUSTE DE ENTRADA | K13: BARELLA PLAST | L13: 1010870 | M13: 03_26
A14: 0053-54 | B14: =IF(ISERROR(VLOOKUP($A14,'[1]BASE DIVERGÊNCIA'!$A$2:$B$1048576,2,0)),0,VLOOKUP($A14,'[1]BASE DIVERGÊNCIA'!$A$2:$B$1048576,2,0)) -> MASTER REMAFIM BRANCO TAR 602764-12 | C14: 485.521 | D14: ='PLANILHA MESTRE'!O147 -> 186.43158 | F14: =D14+E14-C14 -> -299.08942 | G14: =IF(ISERROR(VLOOKUP($A14,'[1]BASE DIVERGÊNCIA'!$A$2:$D$1048576,4,0)),0,VLOOKUP($A14,'[1]BASE DIVERGÊNCIA'!$A$2:$D$1048576,4,0)) -> KG | H14: =IF(OR(C14=0,ISBLANK(C14)),"100%",F14/C14) -> -0.61601747 | I14: =IF(H14<-2%,"VENDA",IF(H14<0%,"AJUSTE DE SAÍDA",IF(H14>0,"AJUSTE DE ENTRADA","SEM DIFERENÇA"))) -> VENDA | K14: BARELLA PLAST | L14: 1010870 | M14: 03_26
A15: 0103-02 | B15: =IF(ISERROR(VLOOKUP($A15,'[1]BASE DIVERGÊNCIA'!$A$2:$B$1048576,2,0)),0,VLOOKUP($A15,'[1]BASE DIVERGÊNCIA'!$A$2:$B$1048576,2,0)) -> PORCA SEXT. M8-E X 13 X 6 MM ZC | C15: 31351 | D15: =C15 -> 31351 | F15: =D15+E15-C15 -> 0 | G15: =IF(ISERROR(VLOOKUP($A15,'[1]BASE DIVERGÊNCIA'!$A$2:$D$1048576,4,0)),0,VLOOKUP($A15,'[1]BASE DIVERGÊNCIA'!$A$2:$D$1048576,4,0)) -> UN | H15: =IF(OR(C15=0,ISBLANK(C15)),"100%",F15/C15) -> 0 | I15: =IF(H15<-2%,"VENDA",IF(H15<0%,"AJUSTE DE SAÍDA",IF(H15>0,"AJUSTE DE ENTRADA","SEM DIFERENÇA"))) -> SEM DIFERENÇA | K15: BARELLA PLAST | L15: 1010870 | M15: 03_26
A16: 0053-91 | B16: =IF(ISERROR(VLOOKUP($A16,'[1]BASE DIVERGÊNCIA'!$A$2:$B$1048576,2,0)),0,VLOOKUP($A16,'[1]BASE DIVERGÊNCIA'!$A$2:$B$1048576,2,0)) -> MASTER PRATA 603762 | C16: 28.112 | D16: ='PLANILHA MESTRE'!O149 -> 28.112738 | F16: =D16+E16-C16 -> 0.000738 | G16: =IF(ISERROR(VLOOKUP($A16,'[1]BASE DIVERGÊNCIA'!$A$2:$D$1048576,4,0)),0,VLOOKUP($A16,'[1]BASE DIVERGÊNCIA'!$A$2:$D$1048576,4,0)) -> KG | H16: =IF(OR(C16=0,ISBLANK(C16)),"100%",F16/C16) -> 2.6252134e-05 | I16: =IF(H16<-2%,"VENDA",IF(H16<0%,"AJUSTE DE SAÍDA",IF(H16>0,"AJUSTE DE ENTRADA","SEM DIFERENÇA"))) -> AJUSTE DE ENTRADA | K16: BARELLA PLAST | L16: 1010870 | M16: 03_26
A17: 0053-90 | B17: =IF(ISERROR(VLOOKUP($A17,'[1]BASE DIVERGÊNCIA'!$A$2:$B$1048576,2,0)),0,VLOOKUP($A17,'[1]BASE DIVERGÊNCIA'!$A$2:$B$1048576,2,0)) -> MASTER PRATA 603761 | C17: 117.567 | D17: ='PLANILHA MESTRE'!O150 -> 105.27655 | F17: =D17+E17-C17 -> -12.290455 | G17: =IF(ISERROR(VLOOKUP($A17,'[1]BASE DIVERGÊNCIA'!$A$2:$D$1048576,4,0)),0,VLOOKUP($A17,'[1]BASE DIVERGÊNCIA'!$A$2:$D$1048576,4,0)) -> KG | H17: =IF(OR(C17=0,ISBLANK(C17)),"100%",F17/C17) -> -0.10454001 | I17: =IF(H17<-2%,"VENDA",IF(H17<0%,"AJUSTE DE SAÍDA",IF(H17>0,"AJUSTE DE ENTRADA","SEM DIFERENÇA"))) -> VENDA | K17: BARELLA PLAST | L17: 1010870 | M17: 03_26
A18: 0212-01 | B18: =IF(ISERROR(VLOOKUP($A18,'[1]BASE DIVERGÊNCIA'!$A$2:$B$1048576,2,0)),0,VLOOKUP($A18,'[1]BASE DIVERGÊNCIA'!$A$2:$B$1048576,2,0)) -> ABS NATURAL P/ CROMACAO (IMPORTADO) | C18: 106.668 | D18: =C18 -> 106.668 | F18: =D18+E18-C18 -> 0 | G18: =IF(ISERROR(VLOOKUP($A18,'[1]BASE DIVERGÊNCIA'!$A$2:$D$1048576,4,0)),0,VLOOKUP($A18,'[1]BASE DIVERGÊNCIA'!$A$2:$D$1048576,4,0)) -> KG | H18: =IF(OR(C18=0,ISBLANK(C18)),"100%",F18/C18) -> 0 | I18: =IF(H18<-2%,"VENDA",IF(H18<0%,"AJUSTE DE SAÍDA",IF(H18>0,"AJUSTE DE ENTRADA","SEM DIFERENÇA"))) -> SEM DIFERENÇA | K18: BARELLA PLAST | L18: 1010870 | M18: 03_26
A19: 0153-01 | B19: =IF(ISERROR(VLOOKUP($A19,'[1]BASE DIVERGÊNCIA'!$A$2:$B$1048576,2,0)),0,VLOOKUP($A19,'[1]BASE DIVERGÊNCIA'!$A$2:$B$1048576,2,0)) -> SAN CRISTAL (IMPORTADO) | C19: 21.618 | D19: =C19 -> 21.618 | F19: =D19+E19-C19 -> 0 | G19: =IF(ISERROR(VLOOKUP($A19,'[1]BASE DIVERGÊNCIA'!$A$2:$D$1048576,4,0)),0,VLOOKUP($A19,'[1]BASE DIVERGÊNCIA'!$A$2:$D$1048576,4,0)) -> KG | H19: =IF(OR(C19=0,ISBLANK(C19)),"100%",F19/C19) -> 0 | I19: =IF(H19<-2%,"VENDA",IF(H19<0%,"AJUSTE DE SAÍDA",IF(H19>0,"AJUSTE DE ENTRADA","SEM DIFERENÇA"))) -> SEM DIFERENÇA | K19: BARELLA PLAST | L19: 1010870 | M19: 03_26
A20: 0197-35 | B20: =IF(ISERROR(VLOOKUP($A20,'[1]BASE DIVERGÊNCIA'!$A$2:$B$1048576,2,0)),0,VLOOKUP($A20,'[1]BASE DIVERGÊNCIA'!$A$2:$B$1048576,2,0)) -> ETIQUETA INOX DOS BOTÕES [AFN] | C20: 67725 | D20: ='PLANILHA MESTRE'!O154+840 -> 12723 | E20: =50000+4000 -> 54000 | F20: =D20+E20-C20 -> -1002 | G20: =IF(ISERROR(VLOOKUP($A20,'[1]BASE DIVERGÊNCIA'!$A$2:$D$1048576,4,0)),0,VLOOKUP($A20,'[1]BASE DIVERGÊNCIA'!$A$2:$D$1048576,4,0)) -> UN | H20: =IF(OR(C20=0,ISBLANK(C20)),"100%",F20/C20) -> -0.014795127 | I20: =IF(H20<-2%,"VENDA",IF(H20<0%,"AJUSTE DE SAÍDA",IF(H20>0,"AJUSTE DE ENTRADA","SEM DIFERENÇA"))) -> AJUSTE DE SAÍDA | K20: BARELLA PLAST | L20: 1010870 | M20: 03_26
A21: 0112-46 | B21: =IF(ISERROR(VLOOKUP($A21,'[1]BASE DIVERGÊNCIA'!$A$2:$B$1048576,2,0)),0,VLOOKUP($A21,'[1]BASE DIVERGÊNCIA'!$A$2:$B$1048576,2,0)) -> SACO PLASTICO 30 X 30 | C21: 66000 | D21: ='PLANILHA MESTRE'!O159+7500 -> 65500 | F21: =D21+E21-C21 -> -500 | G21: =IF(ISERROR(VLOOKUP($A21,'[1]BASE DIVERGÊNCIA'!$A$2:$D$1048576,4,0)),0,VLOOKUP($A21,'[1]BASE DIVERGÊNCIA'!$A$2:$D$1048576,4,0)) -> UN | H21: =IF(OR(C21=0,ISBLANK(C21)),"100%",F21/C21) -> -0.0075757576 | I21: =IF(H21<-2%,"VENDA",IF(H21<0%,"AJUSTE DE SAÍDA",IF(H21>0,"AJUSTE DE ENTRADA","SEM DIFERENÇA"))) -> AJUSTE DE SAÍDA | K21: BARELLA PLAST | L21: 1010870 | M21: 03_26
A22: 0153-03 | B22: =IF(ISERROR(VLOOKUP($A22,'[1]BASE DIVERGÊNCIA'!$A$2:$B$1048576,2,0)),0,VLOOKUP($A22,'[1]BASE DIVERGÊNCIA'!$A$2:$B$1048576,2,0)) -> SAN VERMELHO (MASTERIZADO) | C22: 160.695 | D22: ='PLANILHA MESTRE'!O160 -> 116.86907 | F22: =D22+E22-C22 -> -43.825925 | G22: =IF(ISERROR(VLOOKUP($A22,'[1]BASE DIVERGÊNCIA'!$A$2:$D$1048576,4,0)),0,VLOOKUP($A22,'[1]BASE DIVERGÊNCIA'!$A$2:$D$1048576,4,0)) -> KG | H22: =IF(OR(C22=0,ISBLANK(C22)),"100%",F22/C22) -> -0.27272737 | I22: =IF(H22<-2%,"VENDA",IF(H22<0%,"AJUSTE DE SAÍDA",IF(H22>0,"AJUSTE DE ENTRADA","SEM DIFERENÇA"))) -> VENDA | K22: BARELLA PLAST | L22: 1010870 | M22: 03_26
A23: 0049-30 | B23: =IF(ISERROR(VLOOKUP($A23,'[1]BASE DIVERGÊNCIA'!$A$2:$B$1048576,2,0)),0,VLOOKUP($A23,'[1]BASE DIVERGÊNCIA'!$A$2:$B$1048576,2,0)) -> PP NAT FLUIDEZ 26 (CP 202XP) IMPORTADO | C23: 1085.93 | D23: ='PLANILHA MESTRE'!O161-950 -> 1068.485 | F23: =D23+E23-C23 -> -17.444972 | G23: =IF(ISERROR(VLOOKUP($A23,'[1]BASE DIVERGÊNCIA'!$A$2:$D$1048576,4,0)),0,VLOOKUP($A23,'[1]BASE DIVERGÊNCIA'!$A$2:$D$1048576,4,0)) -> KG | H23: =IF(OR(C23=0,ISBLANK(C23)),"100%",F23/C23) -> -0.016064546 | I23: =IF(H23<-2%,"VENDA",IF(H23<0%,"AJUSTE DE SAÍDA",IF(H23>0,"AJUSTE DE ENTRADA","SEM DIFERENÇA"))) -> AJUSTE DE SAÍDA | K23: BARELLA PLAST | L23: 1010870 | M23: 03_26
A24: 0496-78 | B24: =IF(ISERROR(VLOOKUP($A24,'[1]BASE DIVERGÊNCIA'!$A$2:$B$1048576,2,0)),0,VLOOKUP($A24,'[1]BASE DIVERGÊNCIA'!$A$2:$B$1048576,2,0)) -> MOLA DO MANIPULO [VERSÃO B] | C24: 106567 | D24: ='PLANILHA MESTRE'!O162 -> 53947 | E24: 50000 | F24: =D24+E24-C24 -> -2620 | G24: =IF(ISERROR(VLOOKUP($A24,'[1]BASE DIVERGÊNCIA'!$A$2:$D$1048576,4,0)),0,VLOOKUP($A24,'[1]BASE DIVERGÊNCIA'!$A$2:$D$1048576,4,0)) -> UN | H24: =IF(OR(C24=0,ISBLANK(C24)),"100%",F24/C24) -> -0.024585472 | I24: =IF(H24<-2%,"VENDA",IF(H24<0%,"AJUSTE DE SAÍDA",IF(H24>0,"AJUSTE DE ENTRADA","SEM DIFERENÇA"))) -> VENDA | K24: BARELLA PLAST | L24: 1010870 | M24: 03_26
A25: 1317-32 | B25: =IF(ISERROR(VLOOKUP($A25,'[1]BASE DIVERGÊNCIA'!$A$2:$B$1048576,2,0)),0,VLOOKUP($A25,'[1]BASE DIVERGÊNCIA'!$A$2:$B$1048576,2,0)) -> ETIQUETA INOX POLIDO BOTÃO [VTX] | C25: 9500 | D25: ='PLANILHA MESTRE'!O163*1000 -> 9500 | F25: =D25+E25-C25 -> 0 | G25: =IF(ISERROR(VLOOKUP($A25,'[1]BASE DIVERGÊNCIA'!$A$2:$D$1048576,4,0)),0,VLOOKUP($A25,'[1]BASE DIVERGÊNCIA'!$A$2:$D$1048576,4,0)) -> UN | H25: =IF(OR(C25=0,ISBLANK(C25)),"100%",F25/C25) -> 0 | I25: =IF(H25<-2%,"VENDA",IF(H25<0%,"AJUSTE DE SAÍDA",IF(H25>0,"AJUSTE DE ENTRADA","SEM DIFERENÇA"))) -> SEM DIFERENÇA | K25: BARELLA PLAST | L25: 1010870 | M25: 03_26
A26: 0053-85 | B26: =IF(ISERROR(VLOOKUP($A26,'[1]BASE DIVERGÊNCIA'!$A$2:$B$1048576,2,0)),0,VLOOKUP($A26,'[1]BASE DIVERGÊNCIA'!$A$2:$B$1048576,2,0)) -> MASTER PARA SAN VERMELHO SD 697/16 4000 | C26: 0 | D26: ='PLANILHA MESTRE'!O164 -> 0 | F26: =D26+E26-C26 -> 0 | G26: =IF(ISERROR(VLOOKUP($A26,'[1]BASE DIVERGÊNCIA'!$A$2:$D$1048576,4,0)),0,VLOOKUP($A26,'[1]BASE DIVERGÊNCIA'!$A$2:$D$1048576,4,0)) -> KG | H26: =IF(OR(C26=0,ISBLANK(C26)),"100%",F26/C26) -> 100% | I26: =IF(H26<-2%,"VENDA",IF(H26<0%,"AJUSTE DE SAÍDA",IF(H26>0,"AJUSTE DE ENTRADA","SEM DIFERENÇA"))) -> AJUSTE DE ENTRADA | K26: BARELLA PLAST | L26: 1010870 | M26: 03_26
A27: 0054-32 | B27: =IF(ISERROR(VLOOKUP($A27,'[1]BASE DIVERGÊNCIA'!$A$2:$B$1048576,2,0)),0,VLOOKUP($A27,'[1]BASE DIVERGÊNCIA'!$A$2:$B$1048576,2,0)) -> MASTER VERDE P/PP(PP64601726)[PALMEIRAS] | C27: 0 | D27: ='PLANILHA MESTRE'!O166 -> 0 | F27: =D27+E27-C27 -> 0 | G27: =IF(ISERROR(VLOOKUP($A27,'[1]BASE DIVERGÊNCIA'!$A$2:$D$1048576,4,0)),0,VLOOKUP($A27,'[1]BASE DIVERGÊNCIA'!$A$2:$D$1048576,4,0)) -> KG | H27: =IF(OR(C27=0,ISBLANK(C27)),"100%",F27/C27) -> 100% | I27: =IF(H27<-2%,"VENDA",IF(H27<0%,"AJUSTE DE SAÍDA",IF(H27>0,"AJUSTE DE ENTRADA","SEM DIFERENÇA"))) -> AJUSTE DE ENTRADA | K27: BARELLA PLAST | L27: 1010870 | M27: 03_26
A28: 0049-41 | B28: =IF(ISERROR(VLOOKUP($A28,'[1]BASE DIVERGÊNCIA'!$A$2:$B$1048576,2,0)),0,VLOOKUP($A28,'[1]BASE DIVERGÊNCIA'!$A$2:$B$1048576,2,0)) -> PBT PRETO AIR FRYER | C28: 2048.35 | D28: ='PLANILHA MESTRE'!O168+1186 -> 2022.552 | F28: =D28+E28-C28 -> -25.798 | G28: =IF(ISERROR(VLOOKUP($A28,'[1]BASE DIVERGÊNCIA'!$A$2:$D$1048576,4,0)),0,VLOOKUP($A28,'[1]BASE DIVERGÊNCIA'!$A$2:$D$1048576,4,0)) -> KG | H28: =IF(OR(C28=0,ISBLANK(C28)),"100%",F28/C28) -> -0.012594527 | I28: =IF(H28<-2%,"VENDA",IF(H28<0%,"AJUSTE DE SAÍDA",IF(H28>0,"AJUSTE DE ENTRADA","SEM DIFERENÇA"))) -> AJUSTE DE SAÍDA | K28: BARELLA PLAST | L28: 1010870 | M28: 03_26
A29: 0054-66 | B29: =IF(ISERROR(VLOOKUP($A29,'[1]BASE DIVERGÊNCIA'!$A$2:$B$1048576,2,0)),0,VLOOKUP($A29,'[1]BASE DIVERGÊNCIA'!$A$2:$B$1048576,2,0)) -> MASTER PRETO P/ PP CP-202XP | C29: 111.163 | D29: ='PLANILHA MESTRE'!O169+5 -> 109.907 | F29: =D29+E29-C29 -> -1.256 | G29: =IF(ISERROR(VLOOKUP($A29,'[1]BASE DIVERGÊNCIA'!$A$2:$D$1048576,4,0)),0,VLOOKUP($A29,'[1]BASE DIVERGÊNCIA'!$A$2:$D$1048576,4,0)) -> KG | H29: =IF(OR(C29=0,ISBLANK(C29)),"100%",F29/C29) -> -0.011298723 | I29: =IF(H29<-2%,"VENDA",IF(H29<0%,"AJUSTE DE SAÍDA",IF(H29>0,"AJUSTE DE ENTRADA","SEM DIFERENÇA"))) -> AJUSTE DE SAÍDA | K29: BARELLA PLAST | L29: 1010870 | M29: 03_26
A30: 0210-00 | B30: =IF(ISERROR(VLOOKUP($A30,'[1]BASE DIVERGÊNCIA'!$A$2:$B$1048576,2,0)),0,VLOOKUP($A30,'[1]BASE DIVERGÊNCIA'!$A$2:$B$1048576,2,0)) -> ETIQUETA PRETA DO BOTÃO [AFN] | C30: 2400 | D30: =C30 -> 2400 | F30: =D30+E30-C30 -> 0 | G30: =IF(ISERROR(VLOOKUP($A30,'[1]BASE DIVERGÊNCIA'!$A$2:$D$1048576,4,0)),0,VLOOKUP($A30,'[1]BASE DIVERGÊNCIA'!$A$2:$D$1048576,4,0)) -> UN | H30: =IF(OR(C30=0,ISBLANK(C30)),"100%",F30/C30) -> 0 | I30: =IF(H30<-2%,"VENDA",IF(H30<0%,"AJUSTE DE SAÍDA",IF(H30>0,"AJUSTE DE ENTRADA","SEM DIFERENÇA"))) -> SEM DIFERENÇA | K30: BARELLA PLAST | L30: 1010870 | M30: 03_26
A31: 0054-13 | B31: =IF(ISERROR(VLOOKUP($A31,'[1]BASE DIVERGÊNCIA'!$A$2:$B$1048576,2,0)),0,VLOOKUP($A31,'[1]BASE DIVERGÊNCIA'!$A$2:$B$1048576,2,0)) -> MASTER AZUL P/PP TRANSL(PP51601956)[FVN] | C31: 2.81 | D31: =C31 -> 2.81 | F31: =D31+E31-C31 -> 0 | G31: =IF(ISERROR(VLOOKUP($A31,'[1]BASE DIVERGÊNCIA'!$A$2:$D$1048576,4,0)),0,VLOOKUP($A31,'[1]BASE DIVERGÊNCIA'!$A$2:$D$1048576,4,0)) -> KG | H31: =IF(OR(C31=0,ISBLANK(C31)),"100%",F31/C31) -> 0 | I31: =IF(H31<-2%,"VENDA",IF(H31<0%,"AJUSTE DE SAÍDA",IF(H31>0,"AJUSTE DE ENTRADA","SEM DIFERENÇA"))) -> SEM DIFERENÇA | K31: BARELLA PLAST | L31: 1010870 | M31: 03_26
A32: 0054-46 | B32: =IF(ISERROR(VLOOKUP($A32,'[1]BASE DIVERGÊNCIA'!$A$2:$B$1048576,2,0)),0,VLOOKUP($A32,'[1]BASE DIVERGÊNCIA'!$A$2:$B$1048576,2,0)) -> MASTER AZ PARA PC (NC51601057) | C32: 0.5 | D32: =C32 -> 0.5 | F32: =D32+E32-C32 -> 0 | G32: =IF(ISERROR(VLOOKUP($A32,'[1]BASE DIVERGÊNCIA'!$A$2:$D$1048576,4,0)),0,VLOOKUP($A32,'[1]BASE DIVERGÊNCIA'!$A$2:$D$1048576,4,0)) -> KG | H32: =IF(OR(C32=0,ISBLANK(C32)),"100%",F32/C32) -> 0 | I32: =IF(H32<-2%,"VENDA",IF(H32<0%,"AJUSTE DE SAÍDA",IF(H32>0,"AJUSTE DE ENTRADA","SEM DIFERENÇA"))) -> SEM DIFERENÇA | K32: BARELLA PLAST | L32: 1010870 | M32: 03_26
A33: 0112-07 | B33: =IF(ISERROR(VLOOKUP($A33,'[1]BASE DIVERGÊNCIA'!$A$2:$B$1048576,2,0)),0,VLOOKUP($A33,'[1]BASE DIVERGÊNCIA'!$A$2:$B$1048576,2,0)) -> SACO PLASTICO 46 X 57 X 0,03 | C33: 20000 | D33: ='PLANILHA MESTRE'!O157 -> 20000 | F33: =D33+E33-C33 -> 0 | G33: =IF(ISERROR(VLOOKUP($A33,'[1]BASE DIVERGÊNCIA'!$A$2:$D$1048576,4,0)),0,VLOOKUP($A33,'[1]BASE DIVERGÊNCIA'!$A$2:$D$1048576,4,0)) -> UN | H33: =IF(OR(C33=0,ISBLANK(C33)),"100%",F33/C33) -> 0 | I33: =IF(H33<-2%,"VENDA",IF(H33<0%,"AJUSTE DE SAÍDA",IF(H33>0,"AJUSTE DE ENTRADA","SEM DIFERENÇA"))) -> SEM DIFERENÇA | K33: BARELLA PLAST | L33: 1010870 | M33: 03_26
A34: 0118-43 | B34: =IF(ISERROR(VLOOKUP($A34,'[1]BASE DIVERGÊNCIA'!$A$2:$B$1048576,2,0)),0,VLOOKUP($A34,'[1]BASE DIVERGÊNCIA'!$A$2:$B$1048576,2,0)) -> SACO PLASTICO 180 X 200 MM | C34: 131.1 | D34: =C34 -> 131.1 | F34: =D34+E34-C34 -> 0 | G34: =IF(ISERROR(VLOOKUP($A34,'[1]BASE DIVERGÊNCIA'!$A$2:$D$1048576,4,0)),0,VLOOKUP($A34,'[1]BASE DIVERGÊNCIA'!$A$2:$D$1048576,4,0)) -> UN | H34: =IF(OR(C34=0,ISBLANK(C34)),"100%",F34/C34) -> 0 | I34: =IF(H34<-2%,"VENDA",IF(H34<0%,"AJUSTE DE SAÍDA",IF(H34>0,"AJUSTE DE ENTRADA","SEM DIFERENÇA"))) -> SEM DIFERENÇA | K34: BARELLA PLAST | L34: 1010870 | M34: 03_26
A35: 0120-02 | B35: =IF(ISERROR(VLOOKUP($A35,'[1]BASE DIVERGÊNCIA'!$A$2:$B$1048576,2,0)),0,VLOOKUP($A35,'[1]BASE DIVERGÊNCIA'!$A$2:$B$1048576,2,0)) -> ETIQUETA DO BOTÃO PRETA [AFON-12L-AB] | C35: 9925 | D35: ='PLANILHA MESTRE'!O172 -> 9925 | F35: =D35+E35-C35 -> 0 | G35: =IF(ISERROR(VLOOKUP($A35,'[1]BASE DIVERGÊNCIA'!$A$2:$D$1048576,4,0)),0,VLOOKUP($A35,'[1]BASE DIVERGÊNCIA'!$A$2:$D$1048576,4,0)) -> UN | H35: =IF(OR(C35=0,ISBLANK(C35)),"100%",F35/C35) -> 0 | I35: =IF(H35<-2%,"VENDA",IF(H35<0%,"AJUSTE DE SAÍDA",IF(H35>0,"AJUSTE DE ENTRADA","SEM DIFERENÇA"))) -> SEM DIFERENÇA | K35: BARELLA PLAST | L35: 1010870 | M35: 03_26
A36: 0049-36 | B36: =IF(ISERROR(VLOOKUP($A36,'[1]BASE DIVERGÊNCIA'!$A$2:$B$1048576,2,0)),0,VLOOKUP($A36,'[1]BASE DIVERGÊNCIA'!$A$2:$B$1048576,2,0)) -> PP P HB HWI-PLC0 GFPP-30(F1) - UL R/C | C36: 250 | D36: ='PLANILHA MESTRE'!O175+126-26 -> 250 | F36: =D36+E36-C36 -> 0 | G36: =IF(ISERROR(VLOOKUP($A36,'[1]BASE DIVERGÊNCIA'!$A$2:$D$1048576,4,0)),0,VLOOKUP($A36,'[1]BASE DIVERGÊNCIA'!$A$2:$D$1048576,4,0)) -> KG | H36: =IF(OR(C36=0,ISBLANK(C36)),"100%",F36/C36) -> 0 | I36: =IF(H36<-2%,"VENDA",IF(H36<0%,"AJUSTE DE SAÍDA",IF(H36>0,"AJUSTE DE ENTRADA","SEM DIFERENÇA"))) -> SEM DIFERENÇA | K36: BARELLA PLAST | L36: 1010870 | M36: 03_26
A37: 0054-51 | B37: =IF(ISERROR(VLOOKUP($A37,'[1]BASE DIVERGÊNCIA'!$A$2:$B$1048576,2,0)),0,VLOOKUP($A37,'[1]BASE DIVERGÊNCIA'!$A$2:$B$1048576,2,0)) -> MASTER VERMELHO PP 96103/22 SD3300096103 | C37: 55.697 | D37: 5.42 | F37: =D37+E37-C37 -> -50.277 | G37: =IF(ISERROR(VLOOKUP($A37,'[1]BASE DIVERGÊNCIA'!$A$2:$D$1048576,4,0)),0,VLOOKUP($A37,'[1]BASE DIVERGÊNCIA'!$A$2:$D$1048576,4,0)) -> KG | H37: =IF(OR(C37=0,ISBLANK(C37)),"100%",F37/C37) -> -0.90268776 | I37: =IF(H37<-2%,"VENDA",IF(H37<0%,"AJUSTE DE SAÍDA",IF(H37>0,"AJUSTE DE ENTRADA","SEM DIFERENÇA"))) -> VENDA | K37: BARELLA PLAST | L37: 1010870 | M37: 03_26
A38: 0054-75 | B38: =IF(ISERROR(VLOOKUP($A38,'[1]BASE DIVERGÊNCIA'!$A$2:$B$1048576,2,0)),0,VLOOKUP($A38,'[1]BASE DIVERGÊNCIA'!$A$2:$B$1048576,2,0)) -> MASTER CHUMBO PE74601156 | C38: 11.421 | D38: =5.626+3.708+1.5 -> 10.834 | F38: =D38+E38-C38 -> -0.587 | G38: =IF(ISERROR(VLOOKUP($A38,'[1]BASE DIVERGÊNCIA'!$A$2:$D$1048576,4,0)),0,VLOOKUP($A38,'[1]BASE DIVERGÊNCIA'!$A$2:$D$1048576,4,0)) -> KG | H38: =IF(OR(C38=0,ISBLANK(C38)),"100%",F38/C38) -> -0.05139655 | I38: =IF(H38<-2%,"VENDA",IF(H38<0%,"AJUSTE DE SAÍDA",IF(H38>0,"AJUSTE DE ENTRADA","SEM DIFERENÇA"))) -> VENDA | K38: BARELLA PLAST | L38: 1010870 | M38: 03_26
A39: 0120-03 | B39: =IF(ISERROR(VLOOKUP($A39,'[1]BASE DIVERGÊNCIA'!$A$2:$B$1048576,2,0)),0,VLOOKUP($A39,'[1]BASE DIVERGÊNCIA'!$A$2:$B$1048576,2,0)) -> ETIQUETA DO BOTÃO INOX [AFON-12L-AB] | C39: 200 | D39: ='PLANILHA MESTRE'!O173-5160 -> 200 | F39: =D39+E39-C39 -> 0 | G39: =IF(ISERROR(VLOOKUP($A39,'[1]BASE DIVERGÊNCIA'!$A$2:$D$1048576,4,0)),0,VLOOKUP($A39,'[1]BASE DIVERGÊNCIA'!$A$2:$D$1048576,4,0)) -> UN | H39: =IF(OR(C39=0,ISBLANK(C39)),"100%",F39/C39) -> 0 | I39: =IF(H39<-2%,"VENDA",IF(H39<0%,"AJUSTE DE SAÍDA",IF(H39>0,"AJUSTE DE ENTRADA","SEM DIFERENÇA"))) -> SEM DIFERENÇA | K39: BARELLA PLAST | L39: 1010870 | M39: 03_26
A40: 0049-38 | B40: =IF(ISERROR(VLOOKUP($A40,'[1]BASE DIVERGÊNCIA'!$A$2:$B$1048576,2,0)),0,VLOOKUP($A40,'[1]BASE DIVERGÊNCIA'!$A$2:$B$1048576,2,0)) -> PP V HB HWI-PLC0 GFPP-30(F1) - UL R/C | C40: 29 | D40: =C40 -> 29 | F40: =D40+E40-C40 -> 0 | G40: =IF(ISERROR(VLOOKUP($A40,'[1]BASE DIVERGÊNCIA'!$A$2:$D$1048576,4,0)),0,VLOOKUP($A40,'[1]BASE DIVERGÊNCIA'!$A$2:$D$1048576,4,0)) -> KG | H40: =IF(OR(C40=0,ISBLANK(C40)),"100%",F40/C40) -> 0 | I40: =IF(H40<-2%,"VENDA",IF(H40<0%,"AJUSTE DE SAÍDA",IF(H40>0,"AJUSTE DE ENTRADA","SEM DIFERENÇA"))) -> SEM DIFERENÇA | K40: BARELLA PLAST | L40: 1010870 | M40: 03_26
A41: 0103-03 | B41: Porca sextavada da borboleta | C41: 271173 | D41: =C41 -> 271173 | F41: =D41+E41-C41 -> 0 | G41: UN | H41: =IF(OR(C41=0,ISBLANK(C41)),"100%",F41/C41) -> 0 | I41: =IF(H41<-2%,"VENDA",IF(H41<0%,"AJUSTE DE SAÍDA",IF(H41>0,"AJUSTE DE ENTRADA","SEM DIFERENÇA"))) -> SEM DIFERENÇA
...

Sheet Plan1
A1: Material | B1: Texto breve material | C1: Utilização livre
A2: 0005-08E | B2: TAMPA COPO PP BRANCA | C2: 106
A3: 0049-01N | B3: PP NAT FLUIDEZ 14 À 26 (HP550R) | C3: 7684.339
A4: 0049-04 | B4: PP NAT FLUIDEZ 25 À 45 (H503) | C4: 20.296 | D4: =PROCV -> #NAME?
A5: 0049-12 | B5: PBT PRETO [AFN] | C5: 1161.931
A6: 0049-27N | B6: PEBD ANTI-CHAMA [COOKTOP] | C6: 473.283
A7: 0049-33N | B7: POLICARBONATO NATURAL | C7: 12.5
A8: 0049-41 | B8: PBT NOVO PARA AIRFRYER | C8: 2022.972
A9: 0053-01 | B9: MASTER BATCH BR-2000 M 1410(PP-BL-30414) | C9: 95.65
A10: 0053-19 | B10: MASTER BATCH PRETO | C10: 312.744
A11: 0053-54 | B11: MASTER REMAFIM BRANCO TAR 602764-12 | C11: 125.302
A12: 0053-80 | B12: MASTER VERMELHO [RED LINE] | C12: 64.496
A13: 0053-85 | B13: MASTER PARA SAN VERMELHO SD 697/16 4000 | C13: 9.495
A14: 0053-90 | B14: MASTER PRATA 603761 | C14: 95.002
A15: 0053-91 | B15: MASTER PRATA 603762 | C15: 7.214
A16: 0053-95 | B16: MASTER PARA PP MARSALA | C16: 0.252
... A45: 1317-32 | B45: ETIQUETA INOX POLIDO BOTÃO [VTX] | C45: 7118.991
